#VRML_SIM R2021a utf8
WorldInfo {
  basicTimeStep 16
  coordinateSystem "NUE"
}
Viewpoint {
  orientation -0.7070077982040297 -0.6821486995934378 -0.18658275622809223 0.20778176587268696
  position -0.180583483055939 0.1479839892481418 0.44773525055002655
  follow "robot"
  followType "None"
}
TexturedBackground {
}
TexturedBackgroundLight {
}
Floor {
  size 1 1
  appearance Appearance {
    material Material {
      diffuseColor 0.4 0.2 0.2
    }
  }
}
DEF WALL_1 Solid {
  translation 0.5 0.05 0
  children [
    DEF WALL_SHAPE Shape {
      appearance PBRAppearance {
        baseColor 0.12549 0.368627 0.729412
        roughness 1
        metalness 0
      }
      geometry Box {
        size 0.02 0.1 0.98
      }
    }
  ]
  boundingObject USE WALL_SHAPE
}
DEF WALL_2 Solid {
  translation -0.5 0.05 0
  children [
    USE WALL_SHAPE
  ]
  name "solid(1)"
  boundingObject USE WALL_SHAPE
}
DEF WALL_3 Solid {
  translation 0 0.05 -0.5
  rotation 0 1 0 1.5708
  children [
    USE WALL_SHAPE
  ]
  name "solid(2)"
  boundingObject USE WALL_SHAPE
}
DEF WALL_4 Solid {
  translation 0 0.05 0.5
  rotation 0 1 0 1.5708
  children [
    USE WALL_SHAPE
  ]
  name "solid(3)"
  boundingObject USE WALL_SHAPE
}
Robot {
  translation -0.05054478490186565 0.0998674654972969 -0.03826787298823596
  rotation -0.999097311285614 2.874190423946374e-05 -0.042480133659864736 3.1415904184078682
  children [
    DEF HIPLEFT HingeJoint {
      jointParameters HingeJointParameters {
        position 7.878292973943163e-08
        axis 0 1 0
        anchor 0.03 0.02 0
      }
      device [
        DEF hip_left RotationalMotor {
          name "hip_left"
        }
        PositionSensor {
          name "hip_left_pos"
        }
      ]
      endPoint Solid {
        translation 0.029999921183879865 0.04999000000000001 -6.6308115987114976e-06
        rotation 0.0010847621594642191 0.9999992470608469 -0.0005737323389500822 0.00022131639647366173
        children [
          DEF LEGLEFT HingeJoint {
            jointParameters HingeJointParameters {
              position 4.9053484496575095e-08
              axis 0 0 1
              anchor 0 0.04 0
            }
            device [
              DEF leg_left RotationalMotor {
                name "leg_left"
              }
              DEF leg_left_pos PositionSensor {
                name "leg_left_pos"
              }
            ]
            endPoint Solid {
              translation 0 0.04 0
              rotation 0 0 1 5.16191365590357e-08
              children [
                DEF KNEELEFT HingeJoint {
                  jointParameters HingeJointParameters {
                    anchor 0 0 0.04
                  }
                  device [
                    DEF knee_left RotationalMotor {
                      name "knee_left"
                    }
                  ]
                }
                DEF ARMBASEBOX Shape {
                  appearance PBRAppearance {
                    baseColor 0.2 0.2 1
                    metalness 0
                  }
                  geometry Box {
                    size 0.04 0.02 0.08
                  }
                }
              ]
              name "solid(5)"
              boundingObject USE ARMBASEBOX
              physics Physics {
              }
              linearVelocity -1.0242539543564881e-12 1.2274425917400793e-10 2.5589221004231124e-11
              angularVelocity 8.212049974498863e-12 7.302149509368249e-10 1.0611534794263515e-12
            }
          }
          DEF ARMBASEBOX Shape {
            appearance PBRAppearance {
              baseColor 0.2 0.2 1
              metalness 0
            }
            geometry Box {
              size 0.02 0.08 0.02
            }
          }
        ]
        name "solid(1)"
        boundingObject USE ARMBASEBOX
        physics Physics {
        }
        linearVelocity -1.1061714513896854e-11 5.919453814650418e-11 1.366138523649623e-10
        angularVelocity 7.203823848652754e-12 7.366425784091221e-10 6.929310159856191e-13
      }
    }
    DEF HIPRIGHT HingeJoint {
      jointParameters HingeJointParameters {
        position 7.8710162064647e-08
        axis 0 1 0
        anchor -0.03 0.02 0
      }
      device [
        RotationalMotor {
          name "hip_right"
        }
        PositionSensor {
          name "hip_right_pos"
        }
      ]
      endPoint Solid {
        translation -0.030000014933780073 0.049994999999999984 6.637597015653611e-06
        rotation 0.0009112440951088503 0.9999995848170083 -1.0068536152955947e-07 0.00022161551998806697
        children [
          DEF LEGRIGHT HingeJoint {
            jointParameters HingeJointParameters {
              position -4.491951100993439e-06
              axis 0 0 1
              anchor 0 0.04 0
            }
            device [
              RotationalMotor {
                name "leg_right"
              }
              PositionSensor {
                name "leg_right_pos"
              }
            ]
            endPoint Solid {
              translation 0 0.04 0
              rotation 0 0 -1 4.491952508515192e-06
              children [
                DEF KNEERIGHT HingeJoint {
                  jointParameters HingeJointParameters {
                    position 0.800000302461933
                    anchor 0 0 0.04
                  }
                  device [
                    RotationalMotor {
                      name "knee_right"
                    }
                  ]
                }
                DEF ARMBASEBOX Shape {
                  appearance PBRAppearance {
                    baseColor 0.2 0.2 1
                    metalness 0
                  }
                  geometry Box {
                    size 0.04 0.02 0.08
                  }
                }
              ]
              name "solid(5)"
              boundingObject USE ARMBASEBOX
              physics Physics {
              }
              linearVelocity 1.021605727783826e-12 1.24501131599326e-10 -2.56247013286051e-11
              angularVelocity -1.1726983408644704e-11 3.6219147387443435e-11 -8.155442242411918e-13
            }
          }
          DEF ARMBASEBOX Shape {
            appearance PBRAppearance {
              baseColor 0.2 0.2 1
              metalness 0
            }
            geometry Box {
              size 0.02 0.08 0.02
            }
          }
        ]
        name "solid(4)"
        boundingObject USE ARMBASEBOX
        physics Physics {
        }
        linearVelocity 1.1069649678424537e-11 6.007783158489596e-11 -1.367899935346528e-10
        angularVelocity -1.0690034921350964e-11 3.6475414621790777e-11 -9.080856019053866e-13
      }
    }
    DEF BODY Shape {
      appearance PBRAppearance {
        baseColor 1 1 0
        roughness 1
        metalness 0
      }
      geometry Box {
        size 0.1 0.03 0.05
      }
    }
  ]
  boundingObject USE BODY
  physics Physics {
    density -1
    mass 1
  }
  controller "Playbot4AllPlayback"
  linearVelocity 8.68284733539041e-15 -4.991704827341714e-13 -1.7677807619976876e-13
  angularVelocity -2.2347291310027104e-12 -8.287082757434197e-09 -1.8003745472042946e-13
}
