#VRML_SIM R2021a utf8
WorldInfo {
  basicTimeStep 16
  coordinateSystem "NUE"
}
Viewpoint {
  orientation -0.6611688020951723 0.7443364960188757 -0.09390950873248786 0.1981509476449694
  position -0.03553138450182207 0.15279999588865253 0.5626740660261749
  follow "robot"
  followType "None"
}
TexturedBackground {
}
TexturedBackgroundLight {
}
Floor {
  size 1 1
  appearance Appearance {
    material Material {
      diffuseColor 0.4 0.2 0.2
    }
  }
}
DEF WALL_1 Solid {
  translation 0.5 0.05 0
  children [
    DEF WALL_SHAPE Shape {
      appearance PBRAppearance {
        baseColor 0.12549 0.368627 0.729412
        roughness 1
        metalness 0
      }
      geometry Box {
        size 0.02 0.1 0.98
      }
    }
  ]
  boundingObject USE WALL_SHAPE
}
DEF WALL_2 Solid {
  translation -0.5 0.05 0
  children [
    USE WALL_SHAPE
  ]
  name "solid(1)"
  boundingObject USE WALL_SHAPE
}
DEF WALL_3 Solid {
  translation 0 0.05 -0.5
  rotation 0 1 0 1.5708
  children [
    USE WALL_SHAPE
  ]
  name "solid(2)"
  boundingObject USE WALL_SHAPE
}
DEF WALL_4 Solid {
  translation 0 0.05 0.5
  rotation 0 1 0 1.5708
  children [
    USE WALL_SHAPE
  ]
  name "solid(3)"
  boundingObject USE WALL_SHAPE
}
Robot {
  translation -0.0505406116187035 0.13986746542942358 -0.038267801638226774
  rotation -0.9990973112770882 2.8834706422062498e-05 -0.04248013379749266 3.141590410476491
  children [
    DEF HIPLEFT HingeJoint {
      jointParameters HingeJointParameters {
        position 7.966639124128731e-08
        axis 0 1 0
        anchor 0.03 0.02 0
      }
      device [
        DEF hip_left RotationalMotor {
          name "hip_left"
        }
        PositionSensor {
          name "hip_left_pos"
        }
      ]
      endPoint Solid {
        translation 0.029999900000000128 0.08999 -6.621210000001941e-06
        rotation 0.0010847578290256279 0.999999247066858 -0.0005737300491878056 0.00022131727936741067
        children [
          DEF LEGLEFT HingeJoint {
            jointParameters HingeJointParameters {
              position 4.6754811244831274e-08
              axis 0 0 1
              anchor 0 0.04 0
            }
            device [
              DEF leg_left RotationalMotor {
                name "leg_left"
              }
              DEF leg_left_pos PositionSensor {
                name "leg_left_pos"
              }
            ]
            endPoint Solid {
              translation 0 0.04 0
              rotation 0 0 1 4.2146848510894035e-08
              children [
                DEF KNEELEFT HingeJoint {
                  jointParameters HingeJointParameters {
                    anchor 0 0 0.04
                  }
                  device [
                    DEF knee_left RotationalMotor {
                      name "knee_left"
                    }
                  ]
                }
                DEF ARMBASEBOX Shape {
                  appearance PBRAppearance {
                    baseColor 0.2 0.2 1
                    metalness 0
                  }
                  geometry Box {
                    size 0.04 0.02 0.08
                  }
                }
              ]
              name "solid(5)"
              boundingObject USE ARMBASEBOX
              physics Physics {
              }
              linearVelocity 3.676420030582888e-12 9.81707492804084e-11 -2.4126411844115973e-11
              angularVelocity -1.2713587277863316e-11 -7.109154801905456e-10 -7.592379107978432e-13
            }
          }
          DEF ARMBASEBOX Shape {
            appearance PBRAppearance {
              baseColor 0.2 0.2 1
              metalness 0
            }
            geometry Box {
              size 0.02 0.08 0.02
            }
          }
        ]
        name "solid(1)"
        boundingObject USE ARMBASEBOX
        physics Physics {
        }
        linearVelocity 1.231813673907225e-11 4.7329862251643804e-11 -1.3508975029069328e-10
        angularVelocity -1.1530547458282528e-11 -7.173291139027405e-10 -8.642889597073321e-13
      }
    }
    DEF HIPRIGHT HingeJoint {
      jointParameters HingeJointParameters {
        position 7.952430215365861e-08
        axis 0 1 0
        anchor -0.03 0.02 0
      }
      device [
        RotationalMotor {
          name "hip_right"
        }
        PositionSensor {
          name "hip_right_pos"
        }
      ]
      endPoint Solid {
        translation -0.03000000000000012 0.089995 6.645680000000002e-06
        rotation 0.0009112407475197515 0.9999995848200587 -1.006853625859035e-07 0.0002216163315548789
        children [
          DEF LEGRIGHT HingeJoint {
            jointParameters HingeJointParameters {
              position -4.494073532620067e-06
              axis 0 0 1
              anchor 0 0.04 0
            }
            device [
              RotationalMotor {
                name "leg_right"
              }
              PositionSensor {
                name "leg_right_pos"
              }
            ]
            endPoint Solid {
              translation 0 0.04 0
              rotation 0 0 -1 4.494028158074852e-06
              children [
                DEF KNEERIGHT HingeJoint {
                  jointParameters HingeJointParameters {
                    position 0.800000302461933
                    anchor 0 0 0.04
                  }
                  device [
                    RotationalMotor {
                      name "knee_right"
                    }
                  ]
                }
                DEF ARMBASEBOX Shape {
                  appearance PBRAppearance {
                    baseColor 0.2 0.2 1
                    metalness 0
                  }
                  geometry Box {
                    size 0.04 0.02 0.08
                  }
                }
              ]
              name "solid(5)"
              boundingObject USE ARMBASEBOX
              physics Physics {
              }
              linearVelocity -3.683644709786717e-12 9.956735433423562e-11 2.4160417057634445e-11
              angularVelocity 1.6057798561586556e-11 -1.6931952406045678e-11 1.453075324366674e-12
            }
          }
          DEF ARMBASEBOX Shape {
            appearance PBRAppearance {
              baseColor 0.2 0.2 1
              metalness 0
            }
            geometry Box {
              size 0.02 0.08 0.02
            }
          }
        ]
        name "solid(4)"
        boundingObject USE ARMBASEBOX
        physics Physics {
        }
        linearVelocity -1.2337199704923494e-11 4.80270823111084e-11 1.352623852666015e-10
        angularVelocity 1.508652306439676e-11 -1.7179782166097104e-11 1.184448608527836e-12
      }
    }
    DEF BODY Shape {
      appearance PBRAppearance {
        baseColor 1 1 0
        roughness 1
        metalness 0
      }
      geometry Box {
        size 0.1 0.1 0.1
      }
    }
  ]
  boundingObject USE BODY
  physics Physics {
    density -1
    mass 1
  }
  controller "Playbot4AllPlaybackSerial"
  linearVelocity -2.0467875041596614e-14 -4.304752110328991e-13 2.439725545612219e-13
  angularVelocity 2.2219892592545426e-12 8.250093967275578e-09 1.7719159473017508e-13
}
