#VRML_SIM R2021a utf8
WorldInfo {
  basicTimeStep 16
  coordinateSystem "NUE"
}
Viewpoint {
  orientation -0.13842387680469773 -0.9847306202132867 -0.10556721055665572 0.9644582581386777
  position -0.47707496414931877 0.15272672538176527 0.21616456300197537
  follow "robot"
  followType "None"
}
TexturedBackground {
}
TexturedBackgroundLight {
}
Floor {
  size 1 1
  appearance Appearance {
    material Material {
      diffuseColor 0.4 0.2 0.2
    }
  }
}
DEF WALL_1 Solid {
  translation 0.5 0.05 0
  children [
    DEF WALL_SHAPE Shape {
      appearance PBRAppearance {
        baseColor 0.12549 0.368627 0.729412
        roughness 1
        metalness 0
      }
      geometry Box {
        size 0.02 0.1 0.98
      }
    }
  ]
  boundingObject USE WALL_SHAPE
}
DEF WALL_2 Solid {
  translation -0.5 0.05 0
  children [
    USE WALL_SHAPE
  ]
  name "solid(1)"
  boundingObject USE WALL_SHAPE
}
DEF WALL_3 Solid {
  translation 0 0.05 -0.5
  rotation 0 1 0 1.5708
  children [
    USE WALL_SHAPE
  ]
  name "solid(2)"
  boundingObject USE WALL_SHAPE
}
DEF WALL_4 Solid {
  translation 0 0.05 0.5
  rotation 0 1 0 1.5708
  children [
    USE WALL_SHAPE
  ]
  name "solid(3)"
  boundingObject USE WALL_SHAPE
}
Robot {
  translation -0.05474256430502154 0.09986746550012354 -0.04225049677572699
  rotation -0.9999706134923114 2.8401507661245264e-05 -0.007666247136936263 3.1415924270367332
  children [
    DEF HIPLEFT HingeJoint {
      jointParameters HingeJointParameters {
        position 8.972208467694786e-10
        axis 0 1 0
        anchor 0.03 0.02 0
      }
      device [
        DEF hip_left RotationalMotor {
          name "hip_left"
        }
        PositionSensor {
        }
      ]
      endPoint Solid {
        translation 0.02999992118439631 0.04998999999999999 -6.630811604850121e-06
        rotation 0.0010851440658682582 0.9999992465306177 -0.0005739342757421389 0.0002212385153996967
        children [
          DEF LEGLEFT HingeJoint {
            jointParameters HingeJointParameters {
              position -6.905788557257764e-09
              axis 0 0 1
              anchor 0 0.04 0
            }
            device [
              DEF leg_left RotationalMotor {
                name "leg_left"
              }
            ]
            endPoint Solid {
              translation 0 0.04 0
              rotation 0 0 1 0
              children [
                DEF KNEELEFT HingeJoint {
                  jointParameters HingeJointParameters {
                    anchor 0 0 0.04
                  }
                  device [
                    DEF knee_left RotationalMotor {
                      name "knee_left"
                    }
                  ]
                }
                DEF ARMBASEBOX Shape {
                  appearance PBRAppearance {
                    baseColor 0.2 0.2 1
                    metalness 0
                  }
                  geometry Box {
                    size 0.04 0.02 0.08
                  }
                }
              ]
              name "solid(5)"
              boundingObject USE ARMBASEBOX
              physics Physics {
              }
              linearVelocity 3.6213610094543077e-13 9.982448198673881e-11 -2.5464961684672602e-11
              angularVelocity -7.898143728348033e-12 -3.7142031553862393e-10 -5.88475318373794e-14
            }
          }
          DEF ARMBASEBOX Shape {
            appearance PBRAppearance {
              baseColor 0.2 0.2 1
              metalness 0
            }
            geometry Box {
              size 0.02 0.08 0.02
            }
          }
        ]
        name "solid(1)"
        boundingObject USE ARMBASEBOX
        physics Physics {
        }
        linearVelocity 2.148249481176498e-12 4.899386452095199e-11 -1.406904558377833e-10
        angularVelocity -6.7085771003300705e-12 -3.7478608259233215e-10 -2.849963788142045e-13
      }
    }
    DEF HIPRIGHT HingeJoint {
      jointParameters HingeJointParameters {
        position 8.992115127464687e-10
        axis 0 1 0
        anchor -0.03 0.02 0
      }
      device [
        RotationalMotor {
          name "hip_right"
        }
      ]
      endPoint Solid {
        translation -0.030000014934296552 0.049995 6.637597014491576e-06
        rotation 0.0009115641522348274 0.9999995845253068 -1.0068526050736366e-07 0.00022153770999250387
        children [
          DEF LEGRIGHT HingeJoint {
            jointParameters HingeJointParameters {
              position -6.922536455297975e-09
              axis 0 0 1
              anchor 0 0.04 0
            }
            device [
              RotationalMotor {
                name "leg_right"
              }
            ]
            endPoint Solid {
              translation 0 0.04 0
              rotation 0 0 1 0
              children [
                DEF KNEERIGHT HingeJoint {
                  jointParameters HingeJointParameters {
                    position 0.800000302461933
                    anchor 0 0 0.04
                  }
                  device [
                    RotationalMotor {
                      name "knee_right"
                    }
                  ]
                }
                DEF ARMBASEBOX Shape {
                  appearance PBRAppearance {
                    baseColor 0.2 0.2 1
                    metalness 0
                  }
                  geometry Box {
                    size 0.04 0.02 0.08
                  }
                }
              ]
              name "solid(5)"
              boundingObject USE ARMBASEBOX
              physics Physics {
              }
              linearVelocity -3.6393440074325567e-13 1.0128203828461795e-10 2.5514435678555158e-11
              angularVelocity 1.2808790135632219e-11 -3.90968465089285e-10 2.401449645565182e-13
            }
          }
          DEF ARMBASEBOX Shape {
            appearance PBRAppearance {
              baseColor 0.2 0.2 1
              metalness 0
            }
            geometry Box {
              size 0.02 0.08 0.02
            }
          }
        ]
        name "solid(4)"
        boundingObject USE ARMBASEBOX
        physics Physics {
        }
        linearVelocity -2.1394227073357326e-12 4.972616762799474e-11 1.4093679591922761e-10
        angularVelocity 1.1658429460827682e-11 -3.945078929463818e-10 1.3092350272028549e-14
      }
    }
    DEF BODY Shape {
      appearance PBRAppearance {
        baseColor 1 1 0
        roughness 1
        metalness 0
      }
      geometry Box {
        size 0.1 0.03 0.05
      }
    }
  ]
  boundingObject USE BODY
  physics Physics {
    density -1
    mass 1
  }
  controller "Playbot4All"
  linearVelocity 1.0845103430193415e-14 1.249816250492586e-12 2.476118848805317e-13
  angularVelocity 2.960295496647142e-12 8.53597522034195e-09 -1.355903405504418e-13
}
